<robot name="agv">

  <material name="black">
    <color rgba="0.0 0.0 0.0 1.0"/>
  </material>
  <material name="blue">
    <color rgba="0.0 0.0 0.8 1.0"/>
  </material>
  <material name="orange">
    <color rgba="1.0 0.423529411765 0.0392156862745 1.0"/>
  </material>

  
<!-- AGV Base -->
  <link name="base_link">
    <collision>
      <geometry>
        <box size="0.7 0.55 0.75" />
      </geometry>
      <origin xyz="-0.225 0 0.400" rpy="0 0 0" />
    </collision> 
    <visual>
      <geometry>
        <box size="0.7 0.55 0.75" />
      </geometry>
      <origin xyz="-0.225 0 0.400" rpy="0 0 0" />
      <material name="blue"/>
    </visual>
  </link>

<!-- Driven wheel: wheel_left -->
  <link name="wheel_left">
    <visual name="visual">
      <geometry>
        <cylinder length="0.08" radius="0.125"/>
      </geometry>
      <material name="black"/>
    </visual>
  </link>
  
  <joint name="joint_wheel_left" type="continuous">
    <parent link="base_link"/>
    <child link="wheel_left"/>
    <origin xyz="0 0.315 0.125" rpy="-1.5708 0 0"/>
  </joint> 

<!-- Driven wheel: wheel_right -->
  <link name="wheel_right">
    <visual name="visual">
      <geometry>
        <cylinder length="0.08" radius="0.125"/>
      </geometry>
      <material name="black"/>
    </visual>
  </link>
  
  <joint name="joint_wheel_right" type="continuous">
    <parent link="base_link"/>
    <child link="wheel_right"/>
    <origin xyz="0 -0.315 0.125" rpy="1.5708 0 0"/>
  </joint> 

<!-- Caster wheel left -->
  <link name="caster_wheel_left">
    <visual>
      <geometry>
          <sphere radius="0.04"/>
      </geometry>
      <material name="black"/>
    </visual>
  </link>
  
  <joint name="joint_caster_wheel_left" type="continuous">
    <origin xyz="-0.535 0.230 0.04" rpy="0 0 0"/>
    <parent link="base_link"/>
    <child link="caster_wheel_left"/>
  </joint>
  
<!-- Caster wheel right -->
  <link name="caster_wheel_right">
    <visual>
      <geometry>
          <sphere radius="0.04"/>
      </geometry>
      <material name="black"/>
    </visual>
  </link>
  
  <joint name="joint_caster_wheel_right" type="continuous">
    <origin xyz="-0.535 -0.230 0.04" rpy="0 0 0"/>
    <parent link="base_link"/>
    <child link="caster_wheel_right"/>
  </joint>
  
<!-- LRF front -->
  <link name="lrf_front">
    <visual>
      <geometry>
        <cylinder length="0.02" radius="0.1"/>
      </geometry>
      <material name="orange"/>
    </visual>
  </link>
  
  <joint name="lrf_front_joint" type="fixed">
    <parent link="base_link"/>
    <child link="lrf_front"/>
    <origin xyz="0.125 0 0.075" rpy="0 0 3.92699"/>
  </joint>
  
<!-- LRF rear -->
  <link name="lrf_rear">
    <visual>
      <geometry>
        <cylinder length="0.02" radius="0.1"/>
      </geometry>
      <material name="orange"/>
    </visual>
  </link>
  
  <joint name="lrf_rear_joint" type="fixed">
    <parent link="base_link"/>
    <child link="lrf_rear"/>
    <origin xyz="-0.575 0 0.075" rpy="0 0 0.785"/>
  </joint>
  
</robot>
    
