<?xml version="1.0"?>
<robot xmlns:xacro="http://ros.org/wiki/xacro" name="agv_wheel">

  <xacro:macro name="agv_wheel" params="wheel_prefix *joint_pose">

    <link name="${wheel_prefix}_wheel_link">
      <visual>
        <origin xyz="0 0 0" rpy="${pi/2} 0 0" />
        <geometry>
          <cylinder length="${wheel_length}" radius="${wheel_radius}" />
        </geometry>
        <material name="Wheel_${wheel_prefix}" />
      </visual>
      <collision>
        <origin xyz="0 0 0" rpy="${pi/2} 0 0" />
        <geometry>
          <cylinder length="${wheel_length}" radius="${wheel_radius}" />
        </geometry>
      </collision>
    </link>

    <joint name="${wheel_prefix}_wheel" type="continuous">
      <parent link="base_link"/>
      <child link="${wheel_prefix}_wheel_link"/>
      <xacro:insert_block name="joint_pose"/>
      <axis xyz="0 1 0" rpy="0 0 0" />
    </joint>

  </xacro:macro>
</robot>